<?xml version='1.0'?>

<robot name="diffrobot" xmlns:xacro="http://www.ros.org/wiki/xacro">

    <xacro:include filename="$(find diffrobot_description)/urdf/diffrobot.gazebo" /> <!-- include gazebo plugins file -->
    
    <link name="robot_footprint">   <!-- just dumy link before the base link-->
    </link>
    
    <joint name="robot_footprint_joint" type="fixed">
        <parent link="robot_footprint"/>
        <child link="base_link"/>
    </joint>

    <link name="base_link">
        <inertial>
            <origin xyz="0.0 0.0 0.0" rpy="0.0 0.0 0.0"/>
            <mass value="5.0"/>
            <inertia ixx="0.0" ixy="0.0" ixz="0.0" iyy="0.0" iyz="0.0" izz="0.0"/>
        </inertial>
        <visual name="base_link_visual">
            <origin xyz="0.0 0.0 0.0" rpy="0.0 0.0 0.0"/>
            <geometry>
                <box size="0.6 0.4 0.1"/>
            </geometry>
            <material name="">
                <color rgba="0.0 0.0 1.0 1.0"/>
                <texture filename=""/>
            </material>
        </visual>
        <collision>
            <origin xyz="0.0 0.0 0.0" rpy="0.0 0.0 0.0"/>
            <geometry>
                <box size="0.6 0.4 0.1"/>
            </geometry>
        </collision>
    </link>

    <link name="lidar_base_link">
        <inertial>
            <origin xyz="0.0 0.0 0.0" rpy="0.0 0.0 0.0"/>
            <mass value="5.0"/>
            <inertia ixx="0.0" ixy="0.0" ixz="0.0" iyy="0.0" iyz="0.0" izz="0.0"/>
        </inertial>
        <visual name="lidar_base_link_visual">
            <origin xyz="0.0 0.0 0.0" rpy="0.0 0.0 0.0"/>
            <geometry>
                <box size="0.3 0.2 0.1"/>
            </geometry>
            <material name="">
                <color rgba="1.0 1.0 0.0 1.0"/>
                <texture filename=""/>
            </material>
        </visual>
        <collision>
            <origin xyz="0.0 0.0 0.0" rpy="0.0 0.0 0.0"/>
            <geometry>
                <box size="0.3 0.2 0.1"/>
            </geometry>
        </collision>
    </link>


    <joint name="lidar_base_joint" type="fixed">  <!-- continous means that always rotate but revolute means it has a min and max limits-->
        <origin xyz="0.0 0.0 0.1" rpy="0.0 0.0 0.0" />
        <parent link="base_link"/>
        <child link="lidar_base_link"/>
    </joint>

    <link name="left_wheel">
        <inertial>
            <!-- <origin xyz="0.0 0.0 0.0" rpy="1.5707 0.0 0.0"/> origin here from the world -->
            <origin xyz="0.0 0.0 0.0" rpy="-1.5707 0.0 0.0"/>
            <!-- <origin xyz="0.0 0.0 0.0" rpy="0.0 1.5707 1.5707"/>  -->
            <mass value="5.0"/>
            <inertia ixx="0.1" ixy="0.0" ixz="0.0" iyy="0.1" iyz="0.0" izz="0.1"/>
        </inertial>
        <visual name="left_wheel_visual">
            <origin xyz="0.0 0.0 0.0" rpy="0.0 0.0 0.0"/>
            <geometry>
                <cylinder radius="0.1" length="0.05"/>
            </geometry>
            <material name="">
                <color rgba="1.0 0.0 0.0 1.0"/>
                <texture filename=""/>
            </material>
        </visual>
        <collision>
            <origin xyz="0.0 0.0 0.0" rpy="0.0 0.0 0.0"/>
            <geometry>
                <cylinder radius="0.1" length="0.05"/>
            </geometry>
        </collision>
    </link>

    
    <joint name="left_wheel_joint" type="continuous">  <!-- continous means that always rotate but revolute means it has a min and max limits-->
        <!-- <origin xyz="0.0 0.15 0.0" rpy="0.0 1.5707 1.5707" /> origin here from the parent, base link -->
        <origin xyz="0.0 0.24 0.0" rpy="-1.5707 0.0 0.0" />
        <parent link="base_link"/>
        <child link="left_wheel"/>
        <axis xyz="0.0 0.0 1.0"/>    <!-- axis of rotation -->
    </joint>

    <link name="right_wheel">
        <inertial>
            <!-- <origin xyz="0.0 0.0 0.0" rpy="0.0 1.5707 1.5707"/>origin here from the world -->
            <origin xyz="0.0 0.0 0.0" rpy="-1.5707 0.0 0.0"/>
            <mass value="5.0"/>
            <inertia ixx="0.1" ixy="0.0" ixz="0.0" iyy="0.1" iyz="0.0" izz="0.1"/>
        </inertial>
        <visual name="right_wheel_visual">
            <origin xyz="0.0 0.0 0.0" rpy="0.0 0.0 0.0"/>
            <geometry>
                <cylinder radius="0.1" length="0.05"/>
            </geometry>
            <material name="">
                <color rgba="1.0 0.0 0.0 1.0"/>
                <texture filename=""/>
            </material>
        </visual>
        <collision>
            <origin xyz="0.0 0.0 0.0" rpy="0.0 0.0 0.0"/>
            <geometry>
                <cylinder radius="0.1" length="0.05"/>
            </geometry>
        </collision>
    </link>
    

    <joint name="right_wheel_joint" type="continuous">  <!-- continous means that always rotate but revolute means it has a min and max limits-->
        <!-- <origin xyz="0.0 -0.15 0.0" rpy="0.0 1.5707 1.5707" /> origin here from the parent, base link 1.5705 is 90 deg -->
        <origin xyz="0.0 -0.24 0.0" rpy="-1.5707 0.0 0.0" /> 
        <parent link="base_link"/>
        <child link="right_wheel"/>
        <axis xyz="0.0 0.0 1.0"/>
    </joint>

    <link name="front_caster">
        <inertial>
            <origin xyz="0.0 0.0 0.0" rpy="0.0 0.0 0.0"/>
            <mass value="0.0"/>
            <inertia ixx="0.0" ixy="0.0" ixz="0.0" iyy="0.0" iyz="0.0" izz="0.0"/>
        </inertial>
        <visual name="front_caster_visual">
            <origin xyz="0.0 0.0 0.0" rpy="0.0 0.0 0.0"/>
            <geometry>
                <sphere radius="0.0499"/>
            </geometry>
            <material name="">
                <color rgba="0.0 1.0 0.0 1.0"/>
                <texture filename=""/>
            </material>
        </visual>
        <collision>
            <origin xyz="0.0 0.0 0.0" rpy="0.0 0.0 0.0"/>
            <geometry>
                <sphere radius="0.0499"/>
            </geometry>
        </collision>
    </link>

    <joint name="front_caster_joint" type="fixed">
        <origin xyz="0.22 0.0 -0.05" rpy="0.0 0.0 0.0" /> <!-- origin here from the parent, base link -->
        <parent link="base_link"/>
        <child link="front_caster"/>
    </joint>


    <link name="back_caster">
        <inertial>
            <origin xyz="0.0 0.0 0.0" rpy="0.0 0.0 0.0"/>
            <mass value="0.0"/>
            <inertia ixx="0.0" ixy="0.0" ixz="0.0" iyy="0.0" iyz="0.0" izz="0.0"/>
        </inertial>
        <visual name="back_caster_visual">
            <origin xyz="0.0 0.0 0.0" rpy="0.0 0.0 0.0"/>
            <geometry>
                <sphere radius="0.0499"/>
            </geometry>
            <material name="">
                <color rgba="1.0 0.0 0.0 1.0"/>
                <texture filename=""/>
            </material>
        </visual>
        <collision>
            <origin xyz="0.0 0.0 0.0" rpy="0.0 0.0 0.0"/>
            <geometry>
                <sphere radius="0.0499"/>
            </geometry>
        </collision>
    </link>

    <joint name="back_caster_joint" type="fixed">
        <origin xyz="-0.22 0.0 -0.05" rpy="0.0 0.0 0.0" /> <!-- origin here from the parent, base link -->
        <parent link="base_link"/>
        <child link="back_caster"/>
    </joint>
   
    <link name="camera_link">
      <inertial>
        <origin xyz="0.0 0.0 0.0" rpy="0.0 0.0 0.0"/>
        <mass value="0.1"/>
        <inertia ixx="0.0" ixy="0.0" ixz="0.0" iyy="0.0" iyz="0.0" izz="0.0"/>
      </inertial>
      <visual name="kinect_visual">
        <origin xyz="0.0 0.0 0.0" rpy="0.0 0.0 0.0"/>
        <geometry>
          <mesh filename="package://diffrobot_description/meshes/kinect.dae" />
        </geometry>
        <material name="white"/>
      </visual>
      <collision>
        <origin xyz="0.0 0.0 0.0" rpy="0.0 0.0 0.0"/>
        <geometry>
          <box size="0.05 0.05 0.05"/>
        </geometry>
      </collision>
    </link>

    <joint name="camera_joint" type="fixed">
        <origin xyz="0.25 0.0 0.1" rpy="0.0 0.0 0.0"/>
        <parent link="base_link"/>
        <child link="camera_link"/>
        <axis xyz="0.0 0.0 1.0"/>
    </joint>

    <link name="camera_link_optical">
    </link>

    <joint name="camera_optical_joint" type="fixed">
        <origin xyz="0 0 0" rpy="0 0 0"/>
        <parent link="camera_link"/>
        <child link="camera_link_optical"/>
    </joint>


    <!-- <link name="lidar_link">
        <inertial>
            <origin xyz="0.0 0.0 0.0" rpy="0.0 0.0 0.0"/>
            <mass value="0.1"/>
            <inertia ixx="0" ixy="0.0" ixz="0.0" iyy="0" iyz="0.0" izz="0"/>
        </inertial>
        <visual name="lidar_visual">
            <origin xyz="0.0 0.0 0.0" rpy="0.0 0.0 0.0"/>
            <geometry>
            <mesh filename="package://diffrobot_description/meshes/lidar_link.STL"/>
            </geometry>
        </visual>
        <collision>
            <origin xyz="0.0 0.0 0.0" rpy="0.0 0.0 0.0"/>
            <geometry>
            <box size="0.05 0.05 0.05"/>
            </geometry>
        </collision>
    </link> -->


    <!-- <joint name="lidar_joint" type="fixed">
            <origin xyz="0.0 0.0 0.078" rpy="1.5707 0.0 0.0"/>
            <parent link="lidar_base_link"/>
            <child link="lidar_link"/>
        
    </joint>  -->

    <!-- <link name="laser_data_link">
    </link> -->

    <!-- <joint name="laser_data_joint" type="fixed">
            <origin xyz="0 0 0" rpy="0 -1.5707 -1.5707"/>
            <parent link="lidar_link"/>
            <child link="laser_data_link"/>
    </joint> -->


    <link name="ouster_lidar_link">
        <inertial>
            <origin xyz="0.0 0.0 0.0" rpy="0.0 0.0 0.0"/>
            <mass value="0.1"/>
            <inertia ixx="0" ixy="0.0" ixz="0.0" iyy="0" iyz="0.0" izz="0"/>
        </inertial>
        <visual name="ouster_lidar_visual">
            <origin xyz="0.0 0.0 0.0" rpy="0.0 0.0 0.0"/>
            <geometry>
            <mesh filename="package://diffrobot_description/meshes/Ouster.stl" scale=".001 .001 .001"/>
            </geometry>
        </visual>
        <collision>
            <origin xyz="0.0 0.0 0.0" rpy="0.0 0.0 0.0"/>
            <geometry>
            <box size="0.05 0.05 0.05"/>
            </geometry>
        </collision>
    </link>


    <joint name="ouster_lidar_joint" type="fixed">
            <origin xyz="0.0 0.0 0.05" rpy="1.5707 0.0 0.0"/>
            <parent link="lidar_base_link"/>
            <child link="ouster_lidar_link"/>
        
    </joint> 

    <link name="laser_data_link">
    </link>

    <joint name="laser_data_joint" type="fixed">
            <origin xyz="0 0 0" rpy="0 -1.5707 -1.5707"/>
            <parent link="ouster_lidar_link"/>
            <child link="laser_data_link"/>
    </joint>

    

</robot>